<?xml version="1.0"?>
<robot name="wheel" xmlns:xacro="http://www.ros.org/wiki/xacro">

    <xacro:include filename="../common/inertia.xacro" />

    <xacro:macro name="wheel" params="lr parent translateX translateY translateZ">
        <link name="${lr}_wheel">
            <visual>
                <origin xyz="0 0 0" rpy="${M_PI/2} 0  0 " /> 
                <geometry>
                    <cylinder length="${wheel_thickness}" radius="${wheel_radius}" />
                </geometry>
                <material name="Red" />
            </visual>
            
            <collision>
                <origin xyz="0 0 0" rpy="${M_PI/2} 0 0 " />
                <geometry>
                    <cylinder length="${wheel_thickness}" radius="${wheel_radius}" />
                </geometry>
            </collision>
            
            <inertial>
                <mass value="${wheel_mass}" />
                <origin xyz="0 0 0" />
                <cylinder_inertia m="${wheel_mass}" r="${wheel_radius}" h="${wheel_thickness}" />
            </inertial>
        </link>

        <joint name="${lr}_wheel_joint" type="continuous">
            <parent link="${parent}" />
            <child link="${lr}_wheel" />
            <origin xyz="${translateX} ${translateY} ${translateZ}" rpy="0 0 0" /> 
            <axis xyz="0 1 0" rpy="0 0 0" />
            <limit effort="100" velocity="100" />
            <joint_properties damping="0.0" friction="0.0" />
        </joint>

        <transmission name="${lr}_wheel_joint_trans">
            <type>transmission_interface/SimpleTransmission</type>
            <joint name="${lr}_wheel_joint" >
                <hardwareInterface>EffortJointInterface</hardwareInterface>
            </joint>
            <actuator name="${lr}_wheel_joint_motor">
                <hardwareInterface>EffortJointInterface</hardwareInterface>
                <mechanicalReduction>1</mechanicalReduction>
            </actuator>
        </transmission>

        <gazebo reference="${lr}_wheel">
            <mu1 value="1.0" />
            <mu2 value="1.0" />
            <kp  value="10000000.0" />
            <kd  value="1.0" />
            <fdir1 value="1 0 0" />
            <material>Gazebo/White</material>
            <turnGravityOff>false</turnGravityOff>
        </gazebo>
    </xacro:macro>
</robot>
