<?xml version="1.0" ?>
<!-- =================================================================================== -->
<!-- |    This document was autogenerated by xacro from chuck.urdf.xacro               | -->
<!-- |    EDITING THIS FILE BY HAND IS NOT RECOMMENDED                                 | -->
<!-- =================================================================================== -->
<robot name="chuck" xmlns:controller="http://playerstage.sourceforge.net/gazebo/xmlschema/#controller" xmlns:interface="http://playerstage.sourceforge.net/gazebo/xmlschema/#interface" xmlns:sensor="http://playerstage.sourceforge.net/gazebo/xmlschema/#sensor" xmlns:xacro="http://ros.org/wiki/xacro">
  <!-- All units in m-kg-s-radians unit system -->
  <!-- Chassis -->
  <!-- Tray support -->
  <!-- Wheels -->
  <!-- Realsense Position (relative to base_link) -->
  <!-- Sensors -->
  <!-- Realsense -->
  <!-- SICK Lidar -->
  <!--Inertial macros for the box and cylinder. Units are kg*m^2-->
  <material name="Black">
    <color rgba="0.0 0.0 0.0 1.0"/>
  </material>
  <material name="Blue">
    <color rgba="0.0 0.0 0.8 1.0"/>
  </material>
  <material name="Green">
    <color rgba="0.0 0.8 0.0 1.0"/>
  </material>
  <material name="Gray">
    <color rgba="0.7 0.7 0.7 1.0"/>
  </material>
  <material name="DarkGray">
    <color rgba="0.3 0.3 0.3 1.0"/>
  </material>
  <material name="Red">
    <color rgba="0.8 0.0 0.0 1.0"/>
  </material>
  <material name="White">
    <color rgba="1.0 1.0 1.0 1.0"/>
  </material>
  <material name="Yellow">
    <color rgba="0.8 0.8 0.0 1.0"/>
  </material>
  <!--Inertial macros for the box and cylinder. Units are kg*m^2-->
  <!--Inertial macros for the box and cylinder. Units are kg*m^2-->
  <!-- Following values measured on the 3d model -->
  <!-- Following values measured on the 3d model -->
  <!-- Also parameterised in part by the values in turtlebot_properties.urdf.xacro -->
  <!--
  Seems like this weird organization is required for move_base to work properly...
  parent > camera_rgb_frame
  -->
  <!-- Robot footprint -->
  <link name="base_footprint">
    <visual>
      <origin rpy="0 0 0" xyz="0 0 0"/>
      <geometry>
        <box size="0.001 0.001 0.001"/>
      </geometry>
    </visual>
  </link>
  <gazebo reference="base_footprint">
    <material>Gazebo/Blue</material>
    <turnGravityOff>false</turnGravityOff>
  </gazebo>
  <joint name="base_footprint_joint" type="fixed">
    <origin rpy="0 0 0" xyz="0 0 0.1695958"/>
    <parent link="base_footprint"/>
    <child link="base_link"/>
  </joint>
  <!-- Chassis of the robot -->
  <link name="base_link">
    <visual>
      <origin rpy="0 0 0" xyz="0 0 0"/>
      <geometry>
        <box size="0.9772396 0.619125 0.3010916"/>
      </geometry>
      <material name="Blue"/>
    </visual>
    <visual>
      <origin rpy="0 0 0" xyz="0 -0.127 0.4505458"/>
      <geometry>
        <box size="0.05 0.05 0.6"/>
      </geometry>
      <material name="Blue"/>
    </visual>
    <visual>
      <origin rpy="0 0 0" xyz="0 0.127 0.4505458"/>
      <geometry>
        <box size="0.05 0.05 0.6"/>
      </geometry>
      <material name="Blue"/>
    </visual>
    <visual>
      <origin rpy="0 0 0" xyz="0 0 0.7695458"/>
      <geometry>
        <box size="0.863 0.635 0.038"/>
      </geometry>
      <material name="Blue"/>
    </visual>
    <collision>
      <origin rpy="0 0 0" xyz="0 0 0"/>
      <geometry>
        <box size="0.9772396 0.619125 0.3010916"/>
      </geometry>
    </collision>
    <inertial>
      <mass value="86.1826"/>
      <origin xyz="0 0 0"/>
      <inertia ixx="3.40401101272" ixy="0" ixz="0" iyy="3.40401101272" iyz="0" izz="3.40401101272"/>
    </inertial>
  </link>
  <gazebo reference="base_link">
    <material>Gazebo/Blue</material>
    <turnGravityOff>false</turnGravityOff>
  </gazebo>
  <!-- Wheels -->
  <link name="left_wheel">
    <visual>
      <origin rpy="1.57079632679 0  0 " xyz="0 0 0"/>
      <geometry>
        <cylinder length="0.047625" radius="0.1016"/>
      </geometry>
      <material name="Red"/>
    </visual>
    <collision>
      <origin rpy="1.57079632679 0 0 " xyz="0 0 0"/>
      <geometry>
        <cylinder length="0.047625" radius="0.1016"/>
      </geometry>
    </collision>
    <inertial>
      <mass value="2.118276"/>
      <origin xyz="0 0 0"/>
      <inertia ixx="0.00586688676419" ixy="0" ixz="0" iyy="0.00586688676419" iyz="0" izz="0.0109330155533"/>
    </inertial>
  </link>
  <joint name="left_wheel_joint" type="continuous">
    <parent link="base_link"/>
    <child link="left_wheel"/>
    <origin rpy="0 0 0" xyz="0 -0.2661285 -0.0679958"/>
    <axis rpy="0 0 0" xyz="0 1 0"/>
    <limit effort="100" velocity="100"/>
    <joint_properties damping="0.0" friction="0.0"/>
  </joint>
  <transmission name="left_wheel_joint_trans">
    <type>transmission_interface/SimpleTransmission</type>
    <joint name="left_wheel_joint">
      <hardwareInterface>EffortJointInterface</hardwareInterface>
    </joint>
    <actuator name="left_wheel_joint_motor">
      <hardwareInterface>EffortJointInterface</hardwareInterface>
      <mechanicalReduction>1</mechanicalReduction>
    </actuator>
  </transmission>
  <gazebo reference="left_wheel">
    <mu1 value="1.0"/>
    <mu2 value="1.0"/>
    <kp value="10000000.0"/>
    <kd value="1.0"/>
    <fdir1 value="1 0 0"/>
    <material>Gazebo/White</material>
    <turnGravityOff>false</turnGravityOff>
  </gazebo>
  <link name="right_wheel">
    <visual>
      <origin rpy="1.57079632679 0  0 " xyz="0 0 0"/>
      <geometry>
        <cylinder length="0.047625" radius="0.1016"/>
      </geometry>
      <material name="Red"/>
    </visual>
    <collision>
      <origin rpy="1.57079632679 0 0 " xyz="0 0 0"/>
      <geometry>
        <cylinder length="0.047625" radius="0.1016"/>
      </geometry>
    </collision>
    <inertial>
      <mass value="2.118276"/>
      <origin xyz="0 0 0"/>
      <inertia ixx="0.00586688676419" ixy="0" ixz="0" iyy="0.00586688676419" iyz="0" izz="0.0109330155533"/>
    </inertial>
  </link>
  <joint name="right_wheel_joint" type="continuous">
    <parent link="base_link"/>
    <child link="right_wheel"/>
    <origin rpy="0 0 0" xyz="0 0.2661285 -0.0679958"/>
    <axis rpy="0 0 0" xyz="0 1 0"/>
    <limit effort="100" velocity="100"/>
    <joint_properties damping="0.0" friction="0.0"/>
  </joint>
  <transmission name="right_wheel_joint_trans">
    <type>transmission_interface/SimpleTransmission</type>
    <joint name="right_wheel_joint">
      <hardwareInterface>EffortJointInterface</hardwareInterface>
    </joint>
    <actuator name="right_wheel_joint_motor">
      <hardwareInterface>EffortJointInterface</hardwareInterface>
      <mechanicalReduction>1</mechanicalReduction>
    </actuator>
  </transmission>
  <gazebo reference="right_wheel">
    <mu1 value="1.0"/>
    <mu2 value="1.0"/>
    <kp value="10000000.0"/>
    <kd value="1.0"/>
    <fdir1 value="1 0 0"/>
    <material>Gazebo/White</material>
    <turnGravityOff>false</turnGravityOff>
  </gazebo>
  <!-- Castors -->
  <link name="front_caster">
    <visual>
      <origin rpy="1.57079632679 0 0" xyz="0 0.02 0"/>
      <geometry>
        <sphere radius="0.0762"/>
      </geometry>
      <material name="Black"/>
    </visual>
    <collision>
      <origin rpy="1.57079632679 0 0" xyz="0 0 0"/>
      <geometry>
        <sphere radius="0.0762"/>
      </geometry>
    </collision>
    <inertial>
      <mass value="0.453592"/>
      <origin xyz="0 0 0"/>
      <inertia ixx="0.001" ixy="0.0" ixz="0.0" iyy="0.001" iyz="0.0" izz="0.001"/>
    </inertial>
  </link>
  <joint name="caster_front_joint" type="fixed">
    <parent link="base_link"/>
    <child link="front_caster"/>
    <origin rpy="0 0 0" xyz="0.2885948 0 -0.0932958"/>
  </joint>
  <gazebo reference="caster_front_link">
    <turnGravityOff>false</turnGravityOff>
  </gazebo>
  <link name="back_caster">
    <visual>
      <origin rpy="1.57079632679 0 0" xyz="0 0.02 0"/>
      <geometry>
        <sphere radius="0.0762"/>
      </geometry>
      <material name="Black"/>
    </visual>
    <collision>
      <origin rpy="1.57079632679 0 0" xyz="0 0 0"/>
      <geometry>
        <sphere radius="0.0762"/>
      </geometry>
    </collision>
    <inertial>
      <mass value="0.453592"/>
      <origin xyz="0 0 0"/>
      <inertia ixx="0.001" ixy="0.0" ixz="0.0" iyy="0.001" iyz="0.0" izz="0.001"/>
    </inertial>
  </link>
  <joint name="caster_back_joint" type="fixed">
    <parent link="base_link"/>
    <child link="back_caster"/>
    <origin rpy="0 0 0" xyz="-0.3564382 0 -0.0932958"/>
  </joint>
  <gazebo reference="caster_back_link">
    <turnGravityOff>false</turnGravityOff>
  </gazebo>
  <!-- Realsense R200 -->
  <!-- Placing the camera joint -->
  <joint name="camera_joint" type="fixed">
    <origin rpy="3.14159265359 0 0" xyz="0.4886198 0.065 0.0835458"/>
    <parent link="base_link"/>
    <child link="camera_link"/>
  </joint>
  <!-- Mounting the camera at the right position -->
  <link name="camera_link">
    <visual>
      <origin rpy="1.57079632679 0 1.57079632679" xyz="0 0 0"/>
      <geometry>
        <box size="0.00759 0.13 0.01936"/>
      </geometry>
    </visual>
    <collision>
      <origin rpy="0 0 0" xyz="0.003795 0.065 0.00968"/>
      <geometry>
        <box size="0.00759 0.13 0.01936"/>
      </geometry>
    </collision>
    <!-- This inertial field needs doesn't contain reliable data!! -->
    <inertial>
      <mass value="0.564"/>
      <origin xyz="0 0 0"/>
      <inertia ixx="0.003881243" ixy="0.0" ixz="0.0" iyy="0.000498940" iyz="0.0" izz="0.003879257"/>
    </inertial>
  </link>
  <!--
    ==  RGB joints & links ==
    -->
  <joint name="camera_rgb_joint" type="fixed">
    <origin rpy="0 0 0" xyz="0.00425 0.01954 0.01334"/>
    <parent link="camera_link"/>
    <child link="camera_rgb_frame"/>
  </joint>
  <link name="camera_rgb_frame">
    <visual>
      <origin rpy="1.57079632679 0 1.57079632679" xyz="0 0 0"/>
      <geometry>
        <sphere radius="0.005"/>
      </geometry>
      <material name="green">
        <color rgba="0 1 0 1"/>
      </material>
    </visual>
  </link>
  <joint name="camera_rgb_optical_joint" type="fixed">
    <origin rpy="-1.57079632679 0 -1.57079632679" xyz="0 0 0"/>
    <parent link="camera_rgb_frame"/>
    <child link="camera_rgb_optical_frame"/>
  </joint>
  <link name="camera_rgb_optical_frame"/>
  <!--
    ==  Depth joints & links ==
    -->
  <joint name="camera_depth_joint" type="fixed">
    <origin rpy="0 0 0" xyz="0.00425 0.04694 0.01334"/>
    <parent link="camera_link"/>
    <child link="camera_depth_frame"/>
  </joint>
  <link name="camera_depth_frame">
    <visual>
      <origin rpy="1.57079632679 0 1.57079632679" xyz="0 0 0"/>
      <geometry>
        <sphere radius="0.005"/>
      </geometry>
      <material name="green">
        <color rgba="0 0 1 1"/>
      </material>
    </visual>
  </link>
  <joint name="camera_depth_optical_joint" type="fixed">
    <origin rpy="-1.57079632679 0 -1.57079632679" xyz="0 0 0"/>
    <parent link="camera_depth_frame"/>
    <child link="camera_depth_optical_frame"/>
  </joint>
  <link name="camera_depth_optical_frame"/>
  <joint name="laser_frame_joint" type="fixed">
    <origin rpy="3.14159265359 0 0" xyz="0.4886198 0 0"/>
    <parent link="base_footprint"/>
    <child link="laser_frame"/>
  </joint>
  <link name="laser_frame">
    <visual>
      <origin rpy="0 0 0" xyz="0 0 0"/>
      <geometry>
        <sphere radius="0.005"/>
      </geometry>
      <material name="orange">
        <color rgba="0 0 1 1"/>
      </material>
    </visual>
  </link>
  <!-- z_offset: distance between base plate and laser center (= center of mesh) -->
  <link name="sick_lidar_mount_link">
    <inertial>
      <mass value="0.001"/>
      <origin xyz="0 0 0"/>
      <inertia ixx="0.000001" ixy="0.0" ixz="0.0" iyy="0.000001" iyz="0.0" izz="0.000001"/>
    </inertial>
  </link>
  <joint name="sick_lidar_joint" type="fixed">
    <parent link="sick_lidar_mount_link"/>
    <child link="sick_lidar"/>
    <origin rpy="0 0 0" xyz="0 0 0.06296"/>
  </joint>
  <link name="sick_lidar">
    <visual>
      <geometry>
        <mesh filename="package://sick_tim/meshes/sick_tim551.stl"/>
      </geometry>
      <material name="blue">
        <color rgba="0 0 1 1"/>
      </material>
    </visual>
    <collision>
      <geometry>
        <mesh filename="package://sick_tim/meshes/sick_tim551.stl"/>
      </geometry>
    </collision>
    <inertial>
      <mass value="0.25"/>
      <origin xyz="0 0 -0.026"/>
      <inertia ixx="0.0002290832417" ixy="0.0" ixz="0.0" iyy="0.0002290832417" iyz="0.0" izz="0.00014999994"/>
    </inertial>
  </link>
  <gazebo reference="sick_lidar">
    <material value="Gazebo/Blue"/>
    <sensor name="sick_lidar" type="ray">
      <always_on>true</always_on>
      <update_rate>15.0</update_rate>
      <pose>0 0 0 0 0 0</pose>
      <visualize>false</visualize>
      <ray>
        <scan>
          <horizontal>
            <samples>271</samples>
            <resolution>1</resolution>
            <min_angle>-2.357</min_angle>
            <max_angle>2.357</max_angle>
          </horizontal>
        </scan>
        <range>
          <min>0.05</min>
          <max>10.0</max>
          <resolution>0.01</resolution>
        </range>
      </ray>
      <plugin filename="libgazebo_ros_laser.so" name="gazebo_ros_sick_lidar_controller">
        <gaussianNoise>0.005</gaussianNoise>
        <alwaysOn>true</alwaysOn>
        <updateRate>15.0</updateRate>
        <topicName>scan</topicName>
        <frameName>sick_lidar</frameName>
      </plugin>
    </sensor>
  </gazebo>
  <joint name="lidar_laser_frame_joint" type="fixed">
    <origin rpy="3.14159265359 0 0" xyz="0.4600448 0 0.3175"/>
    <parent link="base_footprint"/>
    <child link="sick_lidar_mount_link"/>
  </joint>
  <!-- Differential drive controller  -->
  <gazebo>
    <plugin filename="libgazebo_ros_diff_drive.so" name="differential_drive_controller">
      <rosDebugLevel>Debug</rosDebugLevel>
      <publishWheelTF>True</publishWheelTF>
      <publishTf>1</publishTf>
      <publishWheelJointState>true</publishWheelJointState>
      <alwaysOn>true</alwaysOn>
      <updateRate>100.0</updateRate>
      <leftJoint>left_wheel_joint</leftJoint>
      <rightJoint>right_wheel_joint</rightJoint>
      <wheelSeparation>0.532257</wheelSeparation>
      <wheelDiameter>0.2032</wheelDiameter>
      <broadcastTF>1</broadcastTF>
      <wheelTorque>30</wheelTorque>
      <wheelAcceleration>1.8</wheelAcceleration>
      <commandTopic>cmd_vel</commandTopic>
      <odometryFrame>srsnode_motion/odometry</odometryFrame>
      <odometryTopic>srsnode_motion/odometry</odometryTopic>
      <robotBaseFrame>base_link</robotBaseFrame>
    </plugin>
    <plugin filename="libgazebo_ros_control.so" name="gazebo_ros_control"/>
  </gazebo>
</robot>

